Internal Server Error: /
Traceback (most recent call last):
  File "/home/user/Projects/test_task/.env/lib/python3.5/site-packages/django/core/handlers/exception.py", line 39, in inner
    response = get_response(request)
  File "/home/user/Projects/test_task/.env/lib/python3.5/site-packages/django/core/handlers/base.py", line 187, in _get_response
    response = self.process_exception_by_middleware(e, request)
  File "/home/user/Projects/test_task/.env/lib/python3.5/site-packages/django/core/handlers/base.py", line 185, in _get_response
    response = wrapped_callback(request, *callback_args, **callback_kwargs)
  File "/home/user/Projects/test_task/.env/lib/python3.5/site-packages/django/views/generic/base.py", line 68, in view
    return self.dispatch(request, *args, **kwargs)
  File "/home/user/Projects/test_task/.env/lib/python3.5/site-packages/django/views/generic/base.py", line 88, in dispatch
    return handler(request, *args, **kwargs)
  File "/home/user/Projects/test_task/.env/lib/python3.5/site-packages/django/views/generic/edit.py", line 183, in post
    return self.form_valid(form)
  File "/home/user/Projects/test_task/text_search/search_engine/views.py", line 20, in form_valid
    data = form.save()
  File "/home/user/Projects/test_task/text_search/search_engine/forms.py", line 20, in save
    page = Page.objects.get_page(text)
  File "/home/user/Projects/test_task/text_search/search_engine/models.py", line 9, in get_page
    return get_object_or_404(Page, text__icontains=text)
  File "/home/user/Projects/test_task/.env/lib/python3.5/site-packages/django/shortcuts.py", line 85, in get_object_or_404
    return queryset.get(*args, **kwargs)
  File "/home/user/Projects/test_task/.env/lib/python3.5/site-packages/django/db/models/query.py", line 389, in get
    (self.model._meta.object_name, num)
search_engine.models.MultipleObjectsReturned: get() returned more than one Page -- it returned 3!
